# 23 예외

## 예외
책에 예제에서는 capture 함수를 이용하여 예외처리 방식을 설명하고 있는데  
예외처리에 대한 기본적인 설명도 없이 래퍼 함수를 가져오는 것은 매우매우 아쉬운 설명같아  
capture 함수를 사용하지 않고 try-catch 문을 활용하여 예제를 작성  

책에 나온 예제 포맷변화 에러, 0 나누기 에러, Exception throw 를 다루었음  

Exception 을 활용하는 가장 큰 이유는  
런타임 때 발생하는 에러로 인해 프로그램이 꺼지는 것을 방지하기 위해  
예외가 발생할 수 있는 코드에는 그에 상응하는 대응 코드도 같이 작성하는 것이  
예외처리의 기본적인 목적이라고 할 수 있음  
```kotlin
import atomictest.eq

fun main() {

    try {
        println("1$".toIntOrNull() eq null)
        var i = "1$".toInt()
    } catch (e: NumberFormatException) {
        println("in catch e: NumberFormatException")
        e.printStackTrace()
    }

    try {
        5000 / 0
    } catch (e: ArithmeticException) {
        println("in catch e: ArithmeticException")
        e.printStackTrace()
    }

    try {
        throw NullPointerException()
    } catch (e: NullPointerException) {
        println("in catch e: NullPointerException")
        e.printStackTrace()
    }

}

== result
null
kotlin.Unit
in catch e: NumberFormatException
in catch e: ArithmeticException
in catch e: NullPointerException
java.lang.NumberFormatException: For input string: "1$"
    at java.base/java.lang.NumberFormatException.forInputString(NumberFormatException.java:67)
    at java.base/java.lang.Integer.parseInt(Integer.java:668)
    at java.base/java.lang.Integer.parseInt(Integer.java:786)
    at _2_23_ExceptionKt.main(2_23_Exception.kt:7)
    at _2_23_ExceptionKt.main(2_23_Exception.kt)
java.lang.ArithmeticException: / by zero 
    at _2_23_ExceptionKt.main(2_23_Exception.kt:14)
    at _2_23_ExceptionKt.main(2_23_Exception.kt)
java.lang.NullPointerException
    at _2_23_ExceptionKt.main(2_23_Exception.kt:21)
    at _2_23_ExceptionKt.main(2_23_Exception.kt)

```